<?xml version="1.0"?>
<robot name="slider" xmlns:xacro="http://www.ros.org/wiki/xacro">

<gazebo>
  <plugin name="gazebo_ros_control" filename="libgazebo_ros_control.so">
    <robotNamespace>slider_gazebo</robotNamespace>
  </plugin>
</gazebo>

<material name="blue">
    <color rgba="0 0 0.8 1"/>
  </material>
  <material name="black">
    <color rgba="0 0 0 1"/>
  </material>
  <material name="white">
    <color rgba="1 1 1 1"/>
  </material>

  <link name="base_link">
    <visual>
      <geometry>
        <box size = "0.152 0.178 0.16"/>
      </geometry>
      <material name="black"/>
      <!-- material Gazebo/Orange / -->
      <origin rpy="0 0 0" xyz="0 0 0.6"/>
    </visual>
    <collision>
      <geometry>
        <box size = "0.152 0.178 0.16"/>
      </geometry>
      <origin rpy="0 0 0" xyz="0 0 0.6"/>
    </collision>
    <inertial>
      <origin xyz="-0.016 -0.009 0.6" rpy="0 0 0"/>
      <mass value="2.8488"/>
      <inertia ixx="8.56" ixy="-1.06" ixz="-1.03" iyy="9.13" iyz="0.74" izz="8.41"/>
    </inertial>
  </link>


  <link name="left_base">
    <visual>	
      <geometry>
        <cylinder radius="0.02" length="0.01"/>
      </geometry>
      <material name="white"/>
      <origin rpy="1.57 0 0" xyz="0 0 0"/>
    </visual>
    <collision>
      <geometry>
        <cylinder radius="0.02" length="0.01"/>
      </geometry>
      <origin rpy="1.57 0 0" xyz="0 0 0"/>
    </collision>
    <inertial>
      <mass value="0.001"/>
      <inertia ixx="0.0" ixy="0.0" ixz="0.0" iyy="0.0" iyz="0.0" izz="0.0"/>
    </inertial>
  </link>



  <joint name="left_base_joint" type="revolute">
  	<axis xyz="0 1 0"/>
    <limit effort="1000.0" lower="-1.5707" upper="1.5707" velocity="0.5"/>
    <safety_controller k_velocity="10" k_position="15" soft_lower_limit="-1.3" soft_upper_limit="1.3" />
    <origin rpy="0 0 0" xyz="0 -0.05 0.6"/>
    <parent link="base_link"/>
    <child link="left_base"/>
  </joint>

  <link name="left_leg">
    <visual>
      <geometry>
        <mesh filename="package://slider_gazebo/meshes/leg.STL" />
      </geometry>
      <origin rpy="0 0 0" xyz="0 0 0"/>
      <material name="black"/>
    </visual>
    <collision>
      <geometry>
        <mesh filename="package://slider_gazebo/meshes/leg.STL" />
      </geometry>
      <origin rpy="0 0 0" xyz="0 0 0"/>
    </collision>
    <inertial>
      <origin xyz="0 0 0" rpy="0 0 0"/>
      <mass value="1.53572"/>
      <inertia ixx="49.03" ixy="0.0" ixz="0.0" iyy="49.03" iyz="0.087" izz="0.443"/>
    </inertial>
  </link>


  <joint name="base_to_left_leg" type="prismatic">
  	<axis xyz="0 0 1"/>
    <limit effort="1000.0" lower="-0.2" upper="0.2" velocity="0.5"/>
    <safety_controller k_velocity="10" k_position="15" soft_lower_limit="-0.15" soft_upper_limit="0.15" />
    <origin rpy="0 0 0" xyz="0 -0.1 -0.129"/>
    <parent link="left_base"/>
    <child link="left_leg"/>
  </joint>

  <link name="right_base">
    <visual>	
      <geometry>
        <cylinder radius="0.02" length="0.01"/>
      </geometry>
      <material name="white"/>
      <origin rpy="1.57 0 0" xyz="0 0 0"/>
    </visual>
    <collision>
      <geometry>
        <cylinder radius="0.02" length="0.01"/>
      </geometry>
      <origin rpy="1.57 0 0" xyz="0 0 0"/>
    </collision>
    <inertial>
      <mass value="0.001"/>
      <inertia ixx="0.0" ixy="0.0" ixz="0.0" iyy="0.0" iyz="0.0" izz="0.0"/>
    </inertial>
  </link>

  <joint name="right_base_joint" type="revolute">
  	<axis xyz="0 1 0"/>
    <limit effort="1000.0" lower="-1.5707" upper="1.5707" velocity="0.5"/>
    <safety_controller k_velocity="10" k_position="15" soft_lower_limit="-1.3" soft_upper_limit="1.3" />
    <origin rpy="0 0 0" xyz="0 0.05 0.6"/>
    <parent link="base_link"/>
    <child link="right_base"/>
  </joint>

  <link name="right_leg">
    <visual>
      <geometry>
        <mesh filename="package://slider_gazebo/meshes/leg.STL" />
      </geometry>
      <origin rpy="0 0 0" xyz="0 0 0"/>
      <material name="black"/>
    </visual>
    <collision>
      <geometry>
        <mesh filename="package://slider_gazebo/meshes/leg.STL" />
      </geometry>
      <origin rpy="0 0 0" xyz="0 0 0"/>
    </collision>
    <inertial>
      <origin xyz="0 0 0" rpy="0 0 0"/>
      <mass value="1.53572"/>
      <inertia ixx="49.03" ixy="0.0" ixz="0.0" iyy="49.03" iyz="0.087" izz="0.443"/>
    </inertial>
  </link>


  <joint name="base_to_right_leg" type="prismatic">
  	<axis xyz="0 0 1"/>
    <limit effort="1000.0" lower="-0.2" upper="0.2" velocity="0.5"/>
    <safety_controller k_velocity="10" k_position="15" soft_lower_limit="-0.15" soft_upper_limit="0.15" />
    <origin rpy="0 0 0" xyz="0 0.07 -0.129"/>
    <parent link="right_base"/>
    <child link="right_leg"/>
  </joint>


  <!-- Transmissions used for ros_control -->
  <transmission name="tran1">
    <type>transmission_interface/SimpleTransmission</type>
    <joint name="left_base_joint">
      <hardwareInterface>hardware_interface/EffortJointInterface</hardwareInterface>
    </joint>
    <actuator name="motor1">
      <hardwareInterface>hardware_interface/EffortJointInterface</hardwareInterface>
      <mechanicalReduction>1</mechanicalReduction>
    </actuator>
  </transmission>

  <transmission name="tran2">
    <type>transmission_interface/SimpleTransmission</type>
    <joint name="base_to_left_leg">
      <hardwareInterface>hardware_interface/EffortJointInterface</hardwareInterface>
    </joint>
    <actuator name="motor2">
      <hardwareInterface>hardware_interface/EffortJointInterface</hardwareInterface>
      <mechanicalReduction>1</mechanicalReduction>
    </actuator>
  </transmission>

  <transmission name="tran3">
    <type>transmission_interface/SimpleTransmission</type>
    <joint name="right_base_joint">
      <hardwareInterface>hardware_interface/EffortJointInterface</hardwareInterface>
    </joint>
    <actuator name="motor3">
      <hardwareInterface>hardware_interface/EffortJointInterface</hardwareInterface>
      <mechanicalReduction>1</mechanicalReduction>
    </actuator>
  </transmission>

  <transmission name="tran4">
    <type>transmission_interface/SimpleTransmission</type>
    <joint name="base_to_right_leg">
      <hardwareInterface>hardware_interface/EffortJointInterface</hardwareInterface>
    </joint>
    <actuator name="motor4">
      <hardwareInterface>hardware_interface/EffortJointInterface</hardwareInterface>
      <mechanicalReduction>1</mechanicalReduction>
    </actuator>
  </transmission>

</robot>
